Workbook

Sheet Location Details
A1: LANGUAGE | B1: English | C1: Portuguese | D1: English | E1: German | F1: English | G1: German | H1: French | I1: Spanish | J1: Spanish | K1: Dutch | L1: Swedish | M1: Portuguese
A2: COUNTRYCODE | B2: US | C2: BR | D2: GB | E2: DE | F2: OZ | G2: AU | H2: FR | I2: AG | J2: ES | K2: DU | L2: SV | M2: PR
A3: COUNTRY NAME | B3: USA | C3: BRAZIL | D3: UK | E3: GERMANY | F3: AUSTRALIA | G3: AUSTRIA | H3: FRANCE | I3: ARGENTINA | J3: SPAIN | K3: NETHERLANDS | L3: SWEDEN | M3: BRAZIL
B6: {=TRANSPOSE(A1:M3)} -> LANGUAGE | C6: COUNTRYCODE | D6: COUNTRY NAME | E6: LANGUAGE
B7: English | C7: US | D7: USA | E7: English
B8: Portuguese | C8: BR | D8: BRAZIL | E8: Portuguese
B9: English | C9: GB | D9: UK | E9: English
B10: German | C10: DE | D10: GERMANY | E10: German
B11: English | C11: OZ | D11: AUSTRALIA | E11: English
B12: German | C12: AU | D12: AUSTRIA | E12: German
B13: French | C13: FR | D13: FRANCE | E13: French
B14: Spanish | C14: AG | D14: ARGENTINA | E14: Spanish
B15: Spanish | C15: ES | D15: SPAIN | E15: Spanish
B16: Dutch | C16: DU | D16: NETHERLANDS | E16: Dutch
B17: Swedish | C17: SV | D17: SWEDEN | E17: Swedish
B18: Portuguese | C18: PR | D18: BRAZIL | E18: Portuguese

Sheet Sports Details
A1: SPORTS TYPE | B1: SPORTS | C1: SPORTS TYPE
A2: INDOOR | B2: Cycling Track | C2: INDOOR
A3: INDOOR | B3: Boxing | C3: INDOOR
A4: OUTDOOR | B4: Football | C4: OUTDOOR
A5: OUTDOOR | B5: Alpine Skiing | C5: OUTDOOR
A6: INDOOR | B6: Water Polo | C6: INDOOR
A7: INDOOR | B7: Fencing | C7: INDOOR
A8: OUTDOOR | B8: Cycling Road | C8: OUTDOOR
A9: INDOOR | B9: Curling | C9: INDOOR
A10: INDOOR | B10: Shooting | C10: INDOOR
A11: OUTDOOR | B11: Freestyle Skiing | C11: OUTDOOR
A12: OUTDOOR | B12: Archery | C12: OUTDOOR
... A33: INDOOR | B33: Swimming | C33: INDOOR

Sheet Sportsmen
A1: MEMBER ID | B1: FULL NAME | C1: PREFIX | D1: FIRSTNAME | E1: MIDDLENAME | F1: LASTNAME | G1: BIRTHDATE | H1: ZODIAC | I1: GENDER | J1: COUNTRYCODE | K1: COUNTRY NAME | L1: LANGUAGE | M1: EMAIL | N1: WEIGHT | O1: BLOODTYPE | P1: SPORT LOCATION | Q1: SPORTS | R1: SALARY
A2: 1 | C2: Ms. | D2: Annie | F2: Abbott | G2: 1997 | H2: Libra | I2: Female | J2: US | N2: 94 | O2: A− | Q2: Cycling Track | R2: 80.73 k
A3: 2 | C3: Ms. | D3: Aurelie | F3: Liesuchke | G3: 1992 | H3: Aquarius | I3: Female | J3: US | N3: 84 | O3: O− | Q3: Boxing | R3: 87.47 k
A4: 3 | C4: Sr. | D4: Tomas | E4: Ferreira | F4: Filho | G4: 1969 | H4: Cancer | I4: Male | J4: BR | N4: 53 | O4: A− | Q4: Football | R4: 64.72 k
A5: 4 | C5: Ms. | D5: Darby | F5: Cruickshank | G5: 1975 | H5: Taurus | I5: Female | J5: US | N5: 49 | O5: O− | Q5: Alpine Skiing | R5: 110.8 k
A6: 5 | C6: Dr. | D6: Jaydon | F6: Borer | G6: 1970 | H6: Taurus | I6: Male | J6: US | N6: 85 | O6: B− | Q6: Water Polo | R6: 56.92 k
A7: 6 | C7: Mr. | D7: Moriah | F7: Lynch | G7: 1992 | H7: Sagittarius | I7: Male | J7: US | N7: 83 | O7: O− | Q7: Fencing | R7: 51.13 k
A8: 7 | C8: Ms. | D8: Amiya | F8: Eichmann | G8: 1999 | H8: Leo | I8: Female | J8: US | N8: 61 | O8: B− | Q8: Cycling Road | R8: 65.47 k
A9: 8 | C9: Mr. | D9: Pierce | F9: Rau | G9: 1963 | H9: Taurus | I9: Male | J9: US | N9: 106 | O9: A+ | Q9: Curling | R9: 109.9 k
A10: 9 | C10: Ms. | D10: Amelia | F10: Stevens | G10: 1971 | H10: Aquarius | I10: Female | J10: GB | N10: 65 | O10: A+ | Q10: Shooting | R10: 60.06 k
A11: 10 | C11: Mr. | D11: Toby | F11: Simpson | G11: 1964 | H11: Sagittarius | I11: Male | J11: GB | N11: 63 | O11: O+ | Q11: Cycling Road | R11: 32.76 k
A12: 11 | C12: Sir | D12: Ethan | F12: Murphy | G12: 1986 | H12: Scorpio | I12: Male | J12: GB | N12: 104 | O12: O+ | Q12: Freestyle Skiing | R12: 99.61 k
A13: 12 | C13: Mrs. | D13: Ashley | F13: Wood | G13: 1977 | H13: Libra | I13: Female | J13: GB | N13: 101 | O13: O+ | Q13: Archery | R13: 56.60 k
A14: 13 | C14: Ms. | D14: Megan | F14: Scott | G14: 1977 | H14: Aquarius | I14: Female | J14: GB | N14: 71 | O14: A− | Q14: Rugby | R14: 117.4 k
A15: 14 | C15: Hr. | D15: Helmut | F15: Weinhae | G15: 1959 | H15: Virgo | I15: Male | J15: DE | N15: 68 | O15: A+ | Q15: Canoe Sprint | R15: 64.86 k
A16: 15 | C16: Prof. | D16: Milena | F16: Schotin | G16: 1965 | H16: Pisces | I16: Female | J16: DE | N16: 105 | O16: O+ | Q16: Cycling BMX | R16: 10.24 k
... A39: 38 | C39: M. | D39: Bernard | F39: Hoarau-Guyon | G39: 1983 | H39: Capricorn | I39: Male | J39: FR | N39: 60 | O39: O− | Q39: Cycling Track | R39: 71.35 k
A40: 39 | C40: Sr. | D40: Hidalgo | E40: Cantu | F40: Tercero | G40: 1984 | H40: Sagittarius | I40: Male | J40: AG | N40: 78 | O40: B− | Q40: Canoe Slalom | R40: 116.4 k
A41: 40 | C41: Sr. | D41: Hadalgo | F41: Polanco | G41: 1988 | H41: Gemini | I41: Male | J41: AG | N41: 98 | O41: A− | Q41: Beach Volleyball | R41: 114.1 k
A42: 41 | C42: Sra. | D42: Laura | F42: Oliviera | G42: 1974 | H42: Aquarius | I42: Female | J42: AG | N42: 52 | O42: O− | Q42: Athletics | R42: 79.87 k
A43: 42 | C43: Sra. | D43: Ainhoa | F43: Garza | G43: 1990 | H43: Pisces | I43: Female | J43: ES | N43: 56 | O43: O+ | Q43: Gymnastics Artistic | R43: 102.0 k
A44: 43 | C44: Sra. | D44: Isabel | F44: Banda | G44: 1960 | H44: Capricorn | I44: Female | J44: ES | N44: 102 | O44: O+ | Q44: Canoe Slalom | R44: 50.66 k
A45: 44 | C45: Sra. | D45: Carolota | F45: Mateos | G45: 1965 | H45: Leo | I45: Female | J45: ES | N45: 59 | O45: O− | Q45: Athletics | R45: 58.22 k
A46: 45 | C46: Mw. | D46: Elize | F46: Prins | G46: 1960 | H46: Taurus | I46: Female | J46: DU | N46: 64 | O46: O+ | Q46: Judo | R46: 39.94 k
A47: 46 | C47: dhr. | D47: Ryan | F47: Pham | G47: 1973 | H47: Libra | I47: Male | J47: DU | N47: 99 | O47: B+ | Q47: Beach Volleyball | R47: 44.87 k
A48: 47 | C48: Mw | D48: Elise | F48: Rotteveel | G48: 1968 | H48: Aries | I48: Female | J48: DU | N48: 62 | O48: O− | Q48: Beach Volleyball | R48: 90.48 k
A49: 48 | C49: Fru. | D49: Mirjam | F49: Soderberg | G49: 1997 | H49: Taurus | I49: Female | J49: SV | N49: 50 | O49: O+ | Q49: Football | R49: 38.97 k
A50: 49 | C50: H. | D50: Berndt | F50: Palsson | G50: 1987 | H50: Pisces | I50: Male | J50: SV | N50: 46 | O50: A− | Q50: Biathlon | R50: 35.39 k
A51: 50 | C51: Sr. | D51: Adriano | E51: Pontes | F51: Sobrinho | G51: 1993 | H51: Leo | I51: Male | J51: PR | N51: 93 | O51: A+ | Q51: Swimming | R51: 20.53 k

Sheet Sportsmen-Fisal (Refined) 
A1: MEMBER ID | B1: MEMBER ID | C1: FULL NAME | D1: PREFIX | E1: FIRSTNAME | F1: MIDDLENAME | G1: LASTNAME | H1: BIRTHDATE | I1: ZODIAC | J1: GENDER | K1: COUNTRYCODE | L1: COUNTRY NAME | M1: LANGUAGE | N1: EMAIL | O1: WEIGHT | P1: BLOOD TYPE | Q1: SPORT LOCATION (OLD) | R1: SPORT LOCATION | S1: SPORTS | T1: SALARY (OLD) | U1: SALARY
A2: 1 | B2: =TEXT(A2,"000") -> 001 | C2: =D2 & " " & E2 & " " & F2 & " " & G2 -> Ms. Annie Abbott | D2: Ms. | E2: Annie | G2: Abbott | H2: 1997 | I2: Libra | J2: Female | K2: US | L2: =VLOOKUP(K2,'Location Details'!$C$6:$E$18,2,0) -> USA | M2: =VLOOKUP(K2,'Location Details'!$C$6:$E$18,3,0) -> English | N2: =LOWER(G2 & "." & E2 & IF(M2="English", "@xyz.org", "@xyz.com")) -> abbott.annie@xyz.org | O2: 94 | P2: A− | Q2: =VLOOKUP(S2,'Sports Details'!$B$1:$C$33,2,0) -> INDOOR | R2: =PROPER(TRIM(Q2)) -> Indoor | S2: Cycling Track | T2: 80.73 k | U2: =VALUE(LEFT(T2,LEN(T2)-2)) * 1000 -> 80730
A3: 2 | B3: =TEXT(A3,"000") -> 002 | C3: =D3 & " " & E3 & " " & F3 & " " & G3 -> Ms. Aurelie Liesuchke | D3: Ms. | E3: Aurelie | G3: Liesuchke | H3: 1992 | I3: Aquarius | J3: Female | K3: US | L3: =VLOOKUP(K3,'Location Details'!$C$6:$E$18,2,0) -> USA | M3: =VLOOKUP(K3,'Location Details'!$C$6:$E$18,3,0) -> English | N3: =LOWER(G3 & "." & E3 & IF(M3="English", "@xyz.org", "@xyz.com")) -> liesuchke.aurelie@xyz.org | O3: 84 | P3: O− | Q3: =VLOOKUP(S3,'Sports Details'!$B$1:$C$33,2,0) -> INDOOR | R3: =PROPER(TRIM(Q3)) -> Indoor | S3: Boxing | T3: 87.47 k | U3: =VALUE(LEFT(T3,LEN(T3)-2)) * 1000 -> 87470
A4: 3 | B4: =TEXT(A4,"000") -> 003 | C4: =D4 & " " & E4 & " " & F4 & " " & G4 -> Mr. Tomas Ferreira Filho | D4: Mr. | E4: Tomas | F4: Ferreira | G4: Filho | H4: 1969 | I4: Cancer | J4: Male | K4: BR | L4: =VLOOKUP(K4,'Location Details'!$C$6:$E$18,2,0) -> BRAZIL | M4: =VLOOKUP(K4,'Location Details'!$C$6:$E$18,3,0) -> Portuguese | N4: =LOWER(G4 & "." & E4 & IF(M4="English", "@xyz.org", "@xyz.com")) -> filho.tomas@xyz.com | O4: 53 | P4: A− | Q4: =VLOOKUP(S4,'Sports Details'!$B$1:$C$33,2,0) -> OUTDOOR | R4: =PROPER(TRIM(Q4)) -> Outdoor | S4: Football | T4: 64.72 k | U4: =VALUE(LEFT(T4,LEN(T4)-2)) * 1000 -> 64720
A5: 4 | B5: =TEXT(A5,"000") -> 004 | C5: =D5 & " " & E5 & " " & F5 & " " & G5 -> Ms. Darby Cruickshank | D5: Ms. | E5: Darby | G5: Cruickshank | H5: 1975 | I5: Taurus | J5: Female | K5: US | L5: =VLOOKUP(K5,'Location Details'!$C$6:$E$18,2,0) -> USA | M5: =VLOOKUP(K5,'Location Details'!$C$6:$E$18,3,0) -> English | N5: =LOWER(G5 & "." & E5 & IF(M5="English", "@xyz.org", "@xyz.com")) -> cruickshank.darby@xyz.org | O5: 49 | P5: O− | Q5: =VLOOKUP(S5,'Sports Details'!$B$1:$C$33,2,0) -> OUTDOOR | R5: =PROPER(TRIM(Q5)) -> Outdoor | S5: Alpine Skiing | T5: 110.8 k | U5: =VALUE(LEFT(T5,LEN(T5)-2)) * 1000 -> 110800
A6: 5 | B6: =TEXT(A6,"000") -> 005 | C6: =D6 & " " & E6 & " " & F6 & " " & G6 -> Dr. Jaydon Borer | D6: Dr. | E6: Jaydon | G6: Borer | H6: 1970 | I6: Taurus | J6: Male | K6: US | L6: =VLOOKUP(K6,'Location Details'!$C$6:$E$18,2,0) -> USA | M6: =VLOOKUP(K6,'Location Details'!$C$6:$E$18,3,0) -> English | N6: =LOWER(G6 & "." & E6 & IF(M6="English", "@xyz.org", "@xyz.com")) -> borer.jaydon@xyz.org | O6: 85 | P6: B− | Q6: =VLOOKUP(S6,'Sports Details'!$B$1:$C$33,2,0) -> INDOOR | R6: =PROPER(TRIM(Q6)) -> Indoor | S6: Water Polo | T6: 56.92 k | U6: =VALUE(LEFT(T6,LEN(T6)-2)) * 1000 -> 56920
A7: 6 | B7: =TEXT(A7,"000") -> 006 | C7: =D7 & " " & E7 & " " & F7 & " " & G7 -> Mr. Moriah Lynch | D7: Mr. | E7: Moriah | G7: Lynch | H7: 1992 | I7: Sagittarius | J7: Male | K7: US | L7: =VLOOKUP(K7,'Location Details'!$C$6:$E$18,2,0) -> USA | M7: =VLOOKUP(K7,'Location Details'!$C$6:$E$18,3,0) -> English | N7: =LOWER(G7 & "." & E7 & IF(M7="English", "@xyz.org", "@xyz.com")) -> lynch.moriah@xyz.org | O7: 83 | P7: O− | Q7: =VLOOKUP(S7,'Sports Details'!$B$1:$C$33,2,0) -> INDOOR | R7: =PROPER(TRIM(Q7)) -> Indoor | S7: Fencing | T7: 51.13 k | U7: =VALUE(LEFT(T7,LEN(T7)-2)) * 1000 -> 51130
A8: 7 | B8: =TEXT(A8,"000") -> 007 | C8: =D8 & " " & E8 & " " & F8 & " " & G8 -> Ms. Amiya Eichmann | D8: Ms. | E8: Amiya | G8: Eichmann | H8: 1999 | I8: Leo | J8: Female | K8: US | L8: =VLOOKUP(K8,'Location Details'!$C$6:$E$18,2,0) -> USA | M8: =VLOOKUP(K8,'Location Details'!$C$6:$E$18,3,0) -> English | N8: =LOWER(G8 & "." & E8 & IF(M8="English", "@xyz.org", "@xyz.com")) -> eichmann.amiya@xyz.org | O8: 61 | P8: B− | Q8: =VLOOKUP(S8,'Sports Details'!$B$1:$C$33,2,0) -> OUTDOOR | R8: =PROPER(TRIM(Q8)) -> Outdoor | S8: Cycling Road | T8: 65.47 k | U8: =VALUE(LEFT(T8,LEN(T8)-2)) * 1000 -> 65470
A9: 8 | B9: =TEXT(A9,"000") -> 008 | C9: =D9 & " " & E9 & " " & F9 & " " & G9 -> Mr. Pierce Rau | D9: Mr. | E9: Pierce | G9: Rau | H9: 1963 | I9: Taurus | J9: Male | K9: US | L9: =VLOOKUP(K9,'Location Details'!$C$6:$E$18,2,0) -> USA | M9: =VLOOKUP(K9,'Location Details'!$C$6:$E$18,3,0) -> English | N9: =LOWER(G9 & "." & E9 & IF(M9="English", "@xyz.org", "@xyz.com")) -> rau.pierce@xyz.org | O9: 106 | P9: A+ | Q9: =VLOOKUP(S9,'Sports Details'!$B$1:$C$33,2,0) -> INDOOR | R9: =PROPER(TRIM(Q9)) -> Indoor | S9: Curling | T9: 109.9 k | U9: =VALUE(LEFT(T9,LEN(T9)-2)) * 1000 -> 109900
A10: 9 | B10: =TEXT(A10,"000") -> 009 | C10: =D10 & " " & E10 & " " & F10 & " " & G10 -> Ms. Amelia Stevens | D10: Ms. | E10: Amelia | G10: Stevens | H10: 1971 | I10: Aquarius | J10: Female | K10: GB | L10: =VLOOKUP(K10,'Location Details'!$C$6:$E$18,2,0) -> UK | M10: =VLOOKUP(K10,'Location Details'!$C$6:$E$18,3,0) -> English | N10: =LOWER(G10 & "." & E10 & IF(M10="English", "@xyz.org", "@xyz.com")) -> stevens.amelia@xyz.org | O10: 65 | P10: A+ | Q10: =VLOOKUP(S10,'Sports Details'!$B$1:$C$33,2,0) -> INDOOR | R10: =PROPER(TRIM(Q10)) -> Indoor | S10: Shooting | T10: 60.06 k | U10: =VALUE(LEFT(T10,LEN(T10)-2)) * 1000 -> 60060
A11: 10 | B11: =TEXT(A11,"000") -> 010 | C11: =D11 & " " & E11 & " " & F11 & " " & G11 -> Mr. Toby Simpson | D11: Mr. | E11: Toby | G11: Simpson | H11: 1964 | I11: Sagittarius | J11: Male | K11: GB | L11: =VLOOKUP(K11,'Location Details'!$C$6:$E$18,2,0) -> UK | M11: =VLOOKUP(K11,'Location Details'!$C$6:$E$18,3,0) -> English | N11: =LOWER(G11 & "." & E11 & IF(M11="English", "@xyz.org", "@xyz.com")) -> simpson.toby@xyz.org | O11: 63 | P11: O+ | Q11: =VLOOKUP(S11,'Sports Details'!$B$1:$C$33,2,0) -> OUTDOOR | R11: =PROPER(TRIM(Q11)) -> Outdoor | S11: Cycling Road | T11: 32.76 k | U11: =VALUE(LEFT(T11,LEN(T11)-2)) * 1000 -> 32760
A12: 11 | B12: =TEXT(A12,"000") -> 011 | C12: =D12 & " " & E12 & " " & F12 & " " & G12 -> Sir Ethan Murphy | D12: Sir | E12: Ethan | G12: Murphy | H12: 1986 | I12: Scorpio | J12: Male | K12: GB | L12: =VLOOKUP(K12,'Location Details'!$C$6:$E$18,2,0) -> UK | M12: =VLOOKUP(K12,'Location Details'!$C$6:$E$18,3,0) -> English | N12: =LOWER(G12 & "." & E12 & IF(M12="English", "@xyz.org", "@xyz.com")) -> murphy.ethan@xyz.org | O12: 104 | P12: O+ | Q12: =VLOOKUP(S12,'Sports Details'!$B$1:$C$33,2,0) -> OUTDOOR | R12: =PROPER(TRIM(Q12)) -> Outdoor | S12: Freestyle Skiing | T12: 99.61 k | U12: =VALUE(LEFT(T12,LEN(T12)-2)) * 1000 -> 99610
A13: 12 | B13: =TEXT(A13,"000") -> 012 | C13: =D13 & " " & E13 & " " & F13 & " " & G13 -> Mrs. Ashley Wood | D13: Mrs. | E13: Ashley | G13: Wood | H13: 1977 | I13: Libra | J13: Female | K13: GB | L13: =VLOOKUP(K13,'Location Details'!$C$6:$E$18,2,0) -> UK | M13: =VLOOKUP(K13,'Location Details'!$C$6:$E$18,3,0) -> English | N13: =LOWER(G13 & "." & E13 & IF(M13="English", "@xyz.org", "@xyz.com")) -> wood.ashley@xyz.org | O13: 101 | P13: O+ | Q13: =VLOOKUP(S13,'Sports Details'!$B$1:$C$33,2,0) -> OUTDOOR | R13: =PROPER(TRIM(Q13)) -> Outdoor | S13: Archery | T13: 56.60 k | U13: =VALUE(LEFT(T13,LEN(T13)-2)) * 1000 -> 56600
A14: 13 | B14: =TEXT(A14,"000") -> 013 | C14: =D14 & " " & E14 & " " & F14 & " " & G14 -> Ms. Megan Scott | D14: Ms. | E14: Megan | G14: Scott | H14: 1977 | I14: Aquarius | J14: Female | K14: GB | L14: =VLOOKUP(K14,'Location Details'!$C$6:$E$18,2,0) -> UK | M14: =VLOOKUP(K14,'Location Details'!$C$6:$E$18,3,0) -> English | N14: =LOWER(G14 & "." & E14 & IF(M14="English", "@xyz.org", "@xyz.com")) -> scott.megan@xyz.org | O14: 71 | P14: A− | Q14: =VLOOKUP(S14,'Sports Details'!$B$1:$C$33,2,0) -> OUTDOOR | R14: =PROPER(TRIM(Q14)) -> Outdoor | S14: Rugby | T14: 117.4 k | U14: =VALUE(LEFT(T14,LEN(T14)-2)) * 1000 -> 117400
A15: 14 | B15: =TEXT(A15,"000") -> 014 | C15: =D15 & " " & E15 & " " & F15 & " " & G15 -> Mr. Helmut Weinhae | D15: Mr. | E15: Helmut | G15: Weinhae | H15: 1959 | I15: Virgo | J15: Male | K15: DE | L15: =VLOOKUP(K15,'Location Details'!$C$6:$E$18,2,0) -> GERMANY | M15: =VLOOKUP(K15,'Location Details'!$C$6:$E$18,3,0) -> German | N15: =LOWER(G15 & "." & E15 & IF(M15="English", "@xyz.org", "@xyz.com")) -> weinhae.helmut@xyz.com | O15: 68 | P15: A+ | Q15: =VLOOKUP(S15,'Sports Details'!$B$1:$C$33,2,0) -> OUTDOOR | R15: =PROPER(TRIM(Q15)) -> Outdoor | S15: Canoe Sprint | T15: 64.86 k | U15: =VALUE(LEFT(T15,LEN(T15)-2)) * 1000 -> 64860
A16: 15 | B16: =TEXT(A16,"000") -> 015 | C16: =D16 & " " & E16 & " " & F16 & " " & G16 -> Prof. Milena Schotin | D16: Prof. | E16: Milena | G16: Schotin | H16: 1965 | I16: Pisces | J16: Female | K16: DE | L16: =VLOOKUP(K16,'Location Details'!$C$6:$E$18,2,0) -> GERMANY | M16: =VLOOKUP(K16,'Location Details'!$C$6:$E$18,3,0) -> German | N16: =LOWER(G16 & "." & E16 & IF(M16="English", "@xyz.org", "@xyz.com")) -> schotin.milena@xyz.com | O16: 105 | P16: O+ | Q16: =VLOOKUP(S16,'Sports Details'!$B$1:$C$33,2,0) -> INDOOR | R16: =PROPER(TRIM(Q16)) -> Indoor | S16: Cycling BMX | T16: 10.24 k | U16: =VALUE(LEFT(T16,LEN(T16)-2)) * 1000 -> 10240
... A39: 38 | B39: =TEXT(A39,"000") -> 038 | C39: =D39 & " " & E39 & " " & F39 & " " & G39 -> Mr. Bernard Hoarau-Guyon | D39: Mr. | E39: Bernard | G39: Hoarau-Guyon | H39: 1983 | I39: Capricorn | J39: Male | K39: FR | L39: =VLOOKUP(K39,'Location Details'!$C$6:$E$18,2,0) -> FRANCE | M39: =VLOOKUP(K39,'Location Details'!$C$6:$E$18,3,0) -> French | N39: =LOWER(G39 & "." & E39 & IF(M39="English", "@xyz.org", "@xyz.com")) -> hoarau-guyon.bernard@xyz.com | O39: 60 | P39: O− | Q39: =VLOOKUP(S39,'Sports Details'!$B$1:$C$33,2,0) -> INDOOR | R39: =PROPER(TRIM(Q39)) -> Indoor | S39: Cycling Track | T39: 71.35 k | U39: =VALUE(LEFT(T39,LEN(T39)-2)) * 1000 -> 71350
A40: 39 | B40: =TEXT(A40,"000") -> 039 | C40: =D40 & " " & E40 & " " & F40 & " " & G40 -> Mr. Hidalgo Cantu Tercero | D40: Mr. | E40: Hidalgo | F40: Cantu | G40: Tercero | H40: 1984 | I40: Sagittarius | J40: Male | K40: AG | L40: =VLOOKUP(K40,'Location Details'!$C$6:$E$18,2,0) -> ARGENTINA | M40: =VLOOKUP(K40,'Location Details'!$C$6:$E$18,3,0) -> Spanish | N40: =LOWER(G40 & "." & E40 & IF(M40="English", "@xyz.org", "@xyz.com")) -> tercero.hidalgo@xyz.com | O40: 78 | P40: B− | Q40: =VLOOKUP(S40,'Sports Details'!$B$1:$C$33,2,0) -> OUTDOOR | R40: =PROPER(TRIM(Q40)) -> Outdoor | S40: Canoe Slalom | T40: 116.4 k | U40: =VALUE(LEFT(T40,LEN(T40)-2)) * 1000 -> 116400
A41: 40 | B41: =TEXT(A41,"000") -> 040 | C41: =D41 & " " & E41 & " " & F41 & " " & G41 -> Mr. Hadalgo Polanco | D41: Mr. | E41: Hadalgo | G41: Polanco | H41: 1988 | I41: Gemini | J41: Male | K41: AG | L41: =VLOOKUP(K41,'Location Details'!$C$6:$E$18,2,0) -> ARGENTINA | M41: =VLOOKUP(K41,'Location Details'!$C$6:$E$18,3,0) -> Spanish | N41: =LOWER(G41 & "." & E41 & IF(M41="English", "@xyz.org", "@xyz.com")) -> polanco.hadalgo@xyz.com | O41: 98 | P41: A− | Q41: =VLOOKUP(S41,'Sports Details'!$B$1:$C$33,2,0) -> OUTDOOR | R41: =PROPER(TRIM(Q41)) -> Outdoor | S41: Beach Volleyball | T41: 114.1 k | U41: =VALUE(LEFT(T41,LEN(T41)-2)) * 1000 -> 114100
A42: 41 | B42: =TEXT(A42,"000") -> 041 | C42: =D42 & " " & E42 & " " & F42 & " " & G42 -> Mrs. Laura Oliviera | D42: Mrs. | E42: Laura | G42: Oliviera | H42: 1974 | I42: Aquarius | J42: Female | K42: AG | L42: =VLOOKUP(K42,'Location Details'!$C$6:$E$18,2,0) -> ARGENTINA | M42: =VLOOKUP(K42,'Location Details'!$C$6:$E$18,3,0) -> Spanish | N42: =LOWER(G42 & "." & E42 & IF(M42="English", "@xyz.org", "@xyz.com")) -> oliviera.laura@xyz.com | O42: 52 | P42: O− | Q42: =VLOOKUP(S42,'Sports Details'!$B$1:$C$33,2,0) -> OUTDOOR | R42: =PROPER(TRIM(Q42)) -> Outdoor | S42: Athletics | T42: 79.87 k | U42: =VALUE(LEFT(T42,LEN(T42)-2)) * 1000 -> 79870
A43: 42 | B43: =TEXT(A43,"000") -> 042 | C43: =D43 & " " & E43 & " " & F43 & " " & G43 -> Mrs. Ainhoa Garza | D43: Mrs. | E43: Ainhoa | G43: Garza | H43: 1990 | I43: Pisces | J43: Female | K43: ES | L43: =VLOOKUP(K43,'Location Details'!$C$6:$E$18,2,0) -> SPAIN | M43: =VLOOKUP(K43,'Location Details'!$C$6:$E$18,3,0) -> Spanish | N43: =LOWER(G43 & "." & E43 & IF(M43="English", "@xyz.org", "@xyz.com")) -> garza.ainhoa@xyz.com | O43: 56 | P43: O+ | Q43: =VLOOKUP(S43,'Sports Details'!$B$1:$C$33,2,0) -> INDOOR | R43: =PROPER(TRIM(Q43)) -> Indoor | S43: Gymnastics Artistic | T43: 102.0 k | U43: =VALUE(LEFT(T43,LEN(T43)-2)) * 1000 -> 102000
A44: 43 | B44: =TEXT(A44,"000") -> 043 | C44: =D44 & " " & E44 & " " & F44 & " " & G44 -> Mrs. Isabel Banda | D44: Mrs. | E44: Isabel | G44: Banda | H44: 1960 | I44: Capricorn | J44: Female | K44: ES | L44: =VLOOKUP(K44,'Location Details'!$C$6:$E$18,2,0) -> SPAIN | M44: =VLOOKUP(K44,'Location Details'!$C$6:$E$18,3,0) -> Spanish | N44: =LOWER(G44 & "." & E44 & IF(M44="English", "@xyz.org", "@xyz.com")) -> banda.isabel@xyz.com | O44: 102 | P44: O+ | Q44: =VLOOKUP(S44,'Sports Details'!$B$1:$C$33,2,0) -> OUTDOOR | R44: =PROPER(TRIM(Q44)) -> Outdoor | S44: Canoe Slalom | T44: 50.66 k | U44: =VALUE(LEFT(T44,LEN(T44)-2)) * 1000 -> 50660
A45: 44 | B45: =TEXT(A45,"000") -> 044 | C45: =D45 & " " & E45 & " " & F45 & " " & G45 -> Mrs. Carolota Mateos | D45: Mrs. | E45: Carolota | G45: Mateos | H45: 1965 | I45: Leo | J45: Female | K45: ES | L45: =VLOOKUP(K45,'Location Details'!$C$6:$E$18,2,0) -> SPAIN | M45: =VLOOKUP(K45,'Location Details'!$C$6:$E$18,3,0) -> Spanish | N45: =LOWER(G45 & "." & E45 & IF(M45="English", "@xyz.org", "@xyz.com")) -> mateos.carolota@xyz.com | O45: 59 | P45: O− | Q45: =VLOOKUP(S45,'Sports Details'!$B$1:$C$33,2,0) -> OUTDOOR | R45: =PROPER(TRIM(Q45)) -> Outdoor | S45: Athletics | T45: 58.22 k | U45: =VALUE(LEFT(T45,LEN(T45)-2)) * 1000 -> 58220
A46: 45 | B46: =TEXT(A46,"000") -> 045 | C46: =D46 & " " & E46 & " " & F46 & " " & G46 -> Mrs. Elize Prins | D46: Mrs. | E46: Elize | G46: Prins | H46: 1960 | I46: Taurus | J46: Female | K46: DU | L46: =VLOOKUP(K46,'Location Details'!$C$6:$E$18,2,0) -> NETHERLANDS | M46: =VLOOKUP(K46,'Location Details'!$C$6:$E$18,3,0) -> Dutch | N46: =LOWER(G46 & "." & E46 & IF(M46="English", "@xyz.org", "@xyz.com")) -> prins.elize@xyz.com | O46: 64 | P46: O+ | Q46: =VLOOKUP(S46,'Sports Details'!$B$1:$C$33,2,0) -> INDOOR | R46: =PROPER(TRIM(Q46)) -> Indoor | S46: Judo | T46: 39.94 k | U46: =VALUE(LEFT(T46,LEN(T46)-2)) * 1000 -> 39940
A47: 46 | B47: =TEXT(A47,"000") -> 046 | C47: =D47 & " " & E47 & " " & F47 & " " & G47 -> Mr. Ryan Pham | D47: Mr. | E47: Ryan | G47: Pham | H47: 1973 | I47: Libra | J47: Male | K47: DU | L47: =VLOOKUP(K47,'Location Details'!$C$6:$E$18,2,0) -> NETHERLANDS | M47: =VLOOKUP(K47,'Location Details'!$C$6:$E$18,3,0) -> Dutch | N47: =LOWER(G47 & "." & E47 & IF(M47="English", "@xyz.org", "@xyz.com")) -> pham.ryan@xyz.com | O47: 99 | P47: B+ | Q47: =VLOOKUP(S47,'Sports Details'!$B$1:$C$33,2,0) -> OUTDOOR | R47: =PROPER(TRIM(Q47)) -> Outdoor | S47: Beach Volleyball | T47: 44.87 k | U47: =VALUE(LEFT(T47,LEN(T47)-2)) * 1000 -> 44870
A48: 47 | B48: =TEXT(A48,"000") -> 047 | C48: =D48 & " " & E48 & " " & F48 & " " & G48 -> Mrs. Elise Rotteveel | D48: Mrs. | E48: Elise | G48: Rotteveel | H48: 1968 | I48: Aries | J48: Female | K48: DU | L48: =VLOOKUP(K48,'Location Details'!$C$6:$E$18,2,0) -> NETHERLANDS | M48: =VLOOKUP(K48,'Location Details'!$C$6:$E$18,3,0) -> Dutch | N48: =LOWER(G48 & "." & E48 & IF(M48="English", "@xyz.org", "@xyz.com")) -> rotteveel.elise@xyz.com | O48: 62 | P48: O− | Q48: =VLOOKUP(S48,'Sports Details'!$B$1:$C$33,2,0) -> OUTDOOR | R48: =PROPER(TRIM(Q48)) -> Outdoor | S48: Beach Volleyball | T48: 90.48 k | U48: =VALUE(LEFT(T48,LEN(T48)-2)) * 1000 -> 90480
A49: 48 | B49: =TEXT(A49,"000") -> 048 | C49: =D49 & " " & E49 & " " & F49 & " " & G49 -> Mrs. Mirjam Soderberg | D49: Mrs. | E49: Mirjam | G49: Soderberg | H49: 1997 | I49: Taurus | J49: Female | K49: SV | L49: =VLOOKUP(K49,'Location Details'!$C$6:$E$18,2,0) -> SWEDEN | M49: =VLOOKUP(K49,'Location Details'!$C$6:$E$18,3,0) -> Swedish | N49: =LOWER(G49 & "." & E49 & IF(M49="English", "@xyz.org", "@xyz.com")) -> soderberg.mirjam@xyz.com | O49: 50 | P49: O+ | Q49: =VLOOKUP(S49,'Sports Details'!$B$1:$C$33,2,0) -> OUTDOOR | R49: =PROPER(TRIM(Q49)) -> Outdoor | S49: Football | T49: 38.97 k | U49: =VALUE(LEFT(T49,LEN(T49)-2)) * 1000 -> 38970
A50: 49 | B50: =TEXT(A50,"000") -> 049 | C50: =D50 & " " & E50 & " " & F50 & " " & G50 -> Mr. Berndt Palsson | D50: Mr. | E50: Berndt | G50: Palsson | H50: 1987 | I50: Pisces | J50: Male | K50: SV | L50: =VLOOKUP(K50,'Location Details'!$C$6:$E$18,2,0) -> SWEDEN | M50: =VLOOKUP(K50,'Location Details'!$C$6:$E$18,3,0) -> Swedish | N50: =LOWER(G50 & "." & E50 & IF(M50="English", "@xyz.org", "@xyz.com")) -> palsson.berndt@xyz.com | O50: 46 | P50: A− | Q50: =VLOOKUP(S50,'Sports Details'!$B$1:$C$33,2,0) -> OUTDOOR | R50: =PROPER(TRIM(Q50)) -> Outdoor | S50: Biathlon | T50: 35.39 k | U50: =VALUE(LEFT(T50,LEN(T50)-2)) * 1000 -> 35390
A51: 50 | B51: =TEXT(A51,"000") -> 050 | C51: =D51 & " " & E51 & " " & F51 & " " & G51 -> Mr. Adriano Pontes Sobrinho | D51: Mr. | E51: Adriano | F51: Pontes | G51: Sobrinho | H51: 1993 | I51: Leo | J51: Male | K51: PR | L51: =VLOOKUP(K51,'Location Details'!$C$6:$E$18,2,0) -> BRAZIL | M51: =VLOOKUP(K51,'Location Details'!$C$6:$E$18,3,0) -> Portuguese | N51: =LOWER(G51 & "." & E51 & IF(M51="English", "@xyz.org", "@xyz.com")) -> sobrinho.adriano@xyz.com | O51: 93 | P51: A+ | Q51: =VLOOKUP(S51,'Sports Details'!$B$1:$C$33,2,0) -> INDOOR | R51: =PROPER(TRIM(Q51)) -> Indoor | S51: Swimming | T51: 20.53 k | U51: =VALUE(LEFT(T51,LEN(T51)-2)) * 1000 -> 20530

Sheet Sportsmen-Fisal(Table)
A1: MEMBER ID | B1: FULL NAME | C1: BIRTHYEAR | D1: ZODIAC | E1: GENDER | F1: COUNTRY CODE | G1: COUNTRY NAME | H1: LANGUAGE | I1: EMAIL | J1: WEIGHT | K1: BLOOD TYPE | L1: SPORT LOCATION | M1: SPORTS | N1: SALARY
A2: 001 | B2: Ms. Annie Abbott | C2: 1997 | D2: Libra | E2: Female | F2: US | G2: USA | H2: English | I2: abbott.annie@xyz.org | J2: 94 | K2: A− | L2: Indoor | M2: Cycling Track | N2: 80730
A3: 002 | B3: Ms. Aurelie Liesuchke | C3: 1992 | D3: Aquarius | E3: Female | F3: US | G3: USA | H3: English | I3: liesuchke.aurelie@xyz.org | J3: 84 | K3: O− | L3: Indoor | M3: Boxing | N3: 87470
A4: 003 | B4: Mr. Tomas Ferreira Filho | C4: 1969 | D4: Cancer | E4: Male | F4: BR | G4: BRAZIL | H4: Portuguese | I4: filho.tomas@xyz.com | J4: 53 | K4: A− | L4: Outdoor | M4: Football | N4: 64720
A5: 004 | B5: Ms. Darby Cruickshank | C5: 1975 | D5: Taurus | E5: Female | F5: US | G5: USA | H5: English | I5: cruickshank.darby@xyz.org | J5: 49 | K5: O− | L5: Outdoor | M5: Alpine Skiing | N5: 110800
A6: 005 | B6: Dr. Jaydon Borer | C6: 1970 | D6: Taurus | E6: Male | F6: US | G6: USA | H6: English | I6: borer.jaydon@xyz.org | J6: 85 | K6: B− | L6: Indoor | M6: Water Polo | N6: 56920
A7: 006 | B7: Mr. Moriah Lynch | C7: 1992 | D7: Sagittarius | E7: Male | F7: US | G7: USA | H7: English | I7: lynch.moriah@xyz.org | J7: 83 | K7: O− | L7: Indoor | M7: Fencing | N7: 51130
A8: 007 | B8: Ms. Amiya Eichmann | C8: 1999 | D8: Leo | E8: Female | F8: US | G8: USA | H8: English | I8: eichmann.amiya@xyz.org | J8: 61 | K8: B− | L8: Outdoor | M8: Cycling Road | N8: 65470
A9: 008 | B9: Mr. Pierce Rau | C9: 1963 | D9: Taurus | E9: Male | F9: US | G9: USA | H9: English | I9: rau.pierce@xyz.org | J9: 106 | K9: A+ | L9: Indoor | M9: Curling | N9: 109900
A10: 009 | B10: Ms. Amelia Stevens | C10: 1971 | D10: Aquarius | E10: Female | F10: GB | G10: UK | H10: English | I10: stevens.amelia@xyz.org | J10: 65 | K10: A+ | L10: Indoor | M10: Shooting | N10: 60060
A11: 010 | B11: Mr. Toby Simpson | C11: 1964 | D11: Sagittarius | E11: Male | F11: GB | G11: UK | H11: English | I11: simpson.toby@xyz.org | J11: 63 | K11: O+ | L11: Outdoor | M11: Cycling Road | N11: 32760
A12: 011 | B12: Sir Ethan Murphy | C12: 1986 | D12: Scorpio | E12: Male | F12: GB | G12: UK | H12: English | I12: murphy.ethan@xyz.org | J12: 104 | K12: O+ | L12: Outdoor | M12: Freestyle Skiing | N12: 99610
A13: 012 | B13: Mrs. Ashley Wood | C13: 1977 | D13: Libra | E13: Female | F13: GB | G13: UK | H13: English | I13: wood.ashley@xyz.org | J13: 101 | K13: O+ | L13: Outdoor | M13: Archery | N13: 56600
... A51: 050 | B51: Mr. Adriano Pontes Sobrinho | C51: 1993 | D51: Leo | E51: Male | F51: PR | G51: BRAZIL | H51: Portuguese | I51: sobrinho.adriano@xyz.com | J51: 93 | K51: A+ | L51: Indoor | M51: Swimming | N51: 20530

Sheet Sportsmen-Fisal (Analysis)
A4: Total Candidates
A5: 50
A14: Gender | B14: Candidate Count
A15: Female | B15: 25
A16: Male | B16: 25
A17: Grand Total | B17: 50
A20: Enlisted Sports (Distinct)
A21: 32
A25: Sports | B25: Total Salary
A26: Alpine Skiing | B26: 199560
A27: Archery | B27: 56600
A28: Athletics | B28: 138090
A29: Basketball | B29: 46350
A30: Beach Volleyball | B30: 285210
A31: Biathlon | B31: 35390
A32: Boxing | B32: 87470
A33: Canoe Slalom | B33: 188950
A34: Canoe Sprint | B34: 64860
A35: Curling | B35: 109900
A36: Cycling BMX | B36: 10240
A37: Cycling Mountain Bike | B37: 88790
... A58: Grand Total | B58: 3358670
A64: Country | B64: Total Salary
A65: ARGENTINA | B65: 310370
A66: AUSTRALIA | B66: 503350
A67: AUSTRIA | B67: 124510
A68: BRAZIL | B68: 85250
A69: FRANCE | B69: 612400
A70: GERMANY | B70: 333410
A71: NETHERLANDS | B71: 175290
A72: SPAIN | B72: 210880
A73: SWEDEN | B73: 74360
A74: UK | B74: 366430
A75: USA | B75: 562420
A76: Grand Total | B76: 3358670
A81: Total Candidates | B81: Gender
A82: Country | B82: Female | C82: Male | D82: Grand Total
A83: ARGENTINA | B83: 1 | C83: 2 | D83: 3
A84: AUSTRALIA | B84: 6 | C84: 2 | D84: 8
A85: AUSTRIA | B85: 1 | C85: 2 | D85: 3
...
